Workbook

Sheet significant_snps
A1: SNP | B1: p_value | C1: p_value_fdr | D1: mean_high | E1: mean_low | F1: significant
A2: 1__31104 | B2: 0.00023357494 | C2: 0.0010116601 | D2: 0.021593707 | E2: 0.99105551 | F2: TRUE | G2: =VLOOKUP(A2,Sheet1!C:I,7,FALSE) -> CP01G000011
A3: 1__31410 | B3: 0.0002986271 | C3: 0.0010116601 | D3: 0.01601401 | E3: 0.987824 | F3: TRUE | G3: =VLOOKUP(A3,Sheet1!C:I,7,FALSE) -> CP01G000011
A4: 1__40663 | B4: 0.0002497155 | C4: 0.0010116601 | D4: 0.022907554 | E4: 0.9858574 | F4: TRUE | G4: =VLOOKUP(A4,Sheet1!C:I,7,FALSE) -> CP01G000014
A5: 1__52322 | B5: 0.00028632907 | C5: 0.0010116601 | D5: 0.024166978 | E5: 0.99642117 | F5: TRUE | G5: =VLOOKUP(A5,Sheet1!C:I,7,FALSE) -> CP01G000017
A6: 1__73671 | B6: 0.0002986271 | C6: 0.0010116601 | D6: 0.018676287 | E6: 0.99786825 | F6: TRUE | G6: =VLOOKUP(A6,Sheet1!C:I,7,FALSE) -> CP01G000031
A7: 1__74017 | B7: 0.00038018 | C7: 0.0010116601 | D7: 0.019002216 | E7: 0.99818475 | F7: TRUE | G7: =VLOOKUP(A7,Sheet1!C:I,7,FALSE) -> CP01G000027
A8: 1__82174 | B8: 0.00040528222 | C8: 0.0010116601 | D8: 0.01989329 | E8: 0.99504426 | F8: TRUE | G8: =VLOOKUP(A8,Sheet1!C:I,7,FALSE) -> CP01G000035
A9: 1__83228 | B9: 0.00034455079 | C9: 0.0010116601 | D9: 0.024005146 | E9: 0.99393375 | F9: TRUE | G9: =VLOOKUP(A9,Sheet1!C:I,7,FALSE) -> CP01G000034
A10: 1__83264 | B10: 0.00034455079 | C10: 0.0010116601 | D10: 0.02368938 | E10: 0.99105908 | F10: TRUE | G10: =VLOOKUP(A10,Sheet1!C:I,7,FALSE) -> CP01G000034
A11: 1__84317 | B11: 0.00040528222 | C11: 0.0010116601 | D11: 0.01921317 | E11: 0.99451811 | F11: TRUE | G11: =VLOOKUP(A11,Sheet1!C:I,7,FALSE) -> CP01G000036
A12: 1__85211 | B12: 0.00039008977 | C12: 0.0010116601 | D12: 0.026555485 | E12: 0.99223157 | F12: TRUE | G12: =VLOOKUP(A12,Sheet1!C:I,7,FALSE) -> CP01G000036
A13: 1__85278 | B13: 0.00040528222 | C13: 0.0010116601 | D13: 0.023520191 | E13: 0.99009077 | F13: TRUE | G13: =VLOOKUP(A13,Sheet1!C:I,7,FALSE) -> CP01G000034
... A399: 6__1135691 | B399: 0.010741514 | C399: 0.010741514 | D399: 0.18221468 | E399: 0.99223192 | F399: TRUE | G399: =VLOOKUP(A399,Sheet1!C:I,7,FALSE) -> CP06G000483

Sheet Sheet1
A1: Chr | B1: Pos | C1: ID | D1: Ref | E1: 3-8-11-24-AlleleFreq | G1: Type | H1: Level | I1: GeneID | K1: GeneID
A2: 1 | B2: 31104 | C2: 1__31104 | D2: G | E2: =VLOOKUP(C2,significant_snps!#REF!,6,FALSE) -> #REF! | F2: ANN=A | G2: synonymous_variant | H2: LOW | I2: CP01G000011 | J2: cgd_1g110 | K2: CP01G000011 | L2: hypothetical protein | M2: CP01G000011.mRNA1 | N2: protein_coding | O2: 1/1 | P2: c.792G>A | Q2: p.Ala264Ala | R2: 792/1221 | S2: 792/1221 | T2: 264/406 | U2: ,A | V2: upstream_gene_variant | W2: MODIFIER | X2: CP01G000009 | Y2: CP01G000009 | Z2: transcript | AA2: CP01G000009.mRNA1 | AB2: protein_coding | AC2: c.-4672C>T | AD2: 4672 | AE2: ,A | AF2: upstream_gene_variant | AG2: MODIFIER | AH2: CP01G000012 | AI2: CP01G000012 | AJ2: transcript | AK2: CP01G000012.mRNA1 | AL2: protein_coding | AM2: c.-2173G>A | AN2: 2173 | AO2: ,A | AP2: upstream_gene_variant | AQ2: MODIFIER | AR2: CP01G000013 | AS2: CP01G000013 | AT2: transcript | AU2: CP01G000013.mRNA1 | AV2: protein_coding | AW2: c.-3912G>A | AX2: 3912 | AY2: ,A | AZ2: downstream_gene_variant | BA2: MODIFIER | BB2: CP01G000010 | BC2: CP01G000010 | BD2: transcript | BE2: CP01G000010.mRNA1 | BF2: protein_coding | BG2: c.*1370G>A | BH2: 1370
A3: 1 | B3: 31410 | C3: 1__31410 | D3: A | E3: =VLOOKUP(C3,significant_snps!#REF!,6,FALSE) -> #REF! | F3: ANN=C | G3: synonymous_variant | H3: LOW | I3: CP01G000011 | J3: cgd_1g110 | K3: CP01G000011 | L3: hypothetical protein | M3: CP01G000011.mRNA1 | N3: protein_coding | O3: 1/1 | P3: c.1098A>C | Q3: p.Leu366Leu | R3: 1098/1221 | S3: 1098/1221 | T3: 366/406 | U3: ,C | V3: upstream_gene_variant | W3: MODIFIER | X3: CP01G000009 | Y3: CP01G000009 | Z3: transcript | AA3: CP01G000009.mRNA1 | AB3: protein_coding | AC3: c.-4978T>G | AD3: 4978 | AE3: ,C | AF3: upstream_gene_variant | AG3: MODIFIER | AH3: CP01G000012 | AI3: CP01G000012 | AJ3: transcript | AK3: CP01G000012.mRNA1 | AL3: protein_coding | AM3: c.-1867A>C | AN3: 1867 | AO3: ,C | AP3: upstream_gene_variant | AQ3: MODIFIER | AR3: CP01G000013 | AS3: CP01G000013 | AT3: transcript | AU3: CP01G000013.mRNA1 | AV3: protein_coding | AW3: c.-3606A>C | AX3: 3606 | AY3: ,C | AZ3: downstream_gene_variant | BA3: MODIFIER | BB3: CP01G000010 | BC3: CP01G000010 | BD3: transcript | BE3: CP01G000010.mRNA1 | BF3: protein_coding | BG3: c.*1676A>C | BH3: 1676
A4: 1 | B4: 40663 | C4: 1__40663 | D4: G | E4: =VLOOKUP(C4,significant_snps!#REF!,6,FALSE) -> #REF! | F4: ANN=A | G4: missense_variant | H4: MODERATE | I4: CP01G000014 | J4: cgd_1g140 | K4: CP01G000014 | L4: hypothetical protein | M4: CP01G000014.mRNA1 | N4: protein_coding | O4: 1/1 | P4: c.2533G>A | Q4: p.Ala845Thr | R4: 2533/2892 | S4: 2533/2892 | T4: 845/963 | U4: ,A | V4: upstream_gene_variant | W4: MODIFIER | X4: CP01G000015 | Y4: CP01G000015 | Z4: transcript | AA4: CP01G000015.mRNA1 | AB4: protein_coding | AC4: c.-4120G>A | AD4: 4120 | AE4: ,A | AF4: downstream_gene_variant | AG4: MODIFIER | AH4: CP01G000013 | AI4: CP01G000013 | AJ4: transcript | AK4: CP01G000013.mRNA1 | AL4: protein_coding | AM4: c.*3578G>A | AN4: 3578
A5: 1 | B5: 52322 | C5: 1__52322 | D5: C | E5: =VLOOKUP(C5,significant_snps!#REF!,6,FALSE) -> #REF! | F5: ANN=A | G5: upstream_gene_variant | H5: MODIFIER | I5: CP01G000017 | J5: cgd_1g170 | K5: CP01G000017 | L5: hypothetical protein | M5: CP01G000017.mRNA1 | N5: protein_coding | O5: c.-2714C>A | P5: 2714 | Q5: ,A | R5: upstream_gene_variant | S5: MODIFIER | T5: CP01G000018 | U5: CP01G000018 | V5: transcript | W5: CP01G000018.mRNA1 | X5: protein_coding | Y5: c.-4041C>A | Z5: 4041 | AA5: ,A | AB5: downstream_gene_variant | AC5: MODIFIER | AD5: CP01G000015 | AE5: CP01G000015 | AF5: transcript | AG5: CP01G000015.mRNA1 | AH5: protein_coding | AI5: c.*4546C>A | AJ5: 4546 | AK5: ,A | AL5: downstream_gene_variant | AM5: MODIFIER | AN5: CP01G000016 | AO5: CP01G000016 | AP5: transcript | AQ5: CP01G000016.mRNA1 | AR5: protein_coding | AS5: c.*1276C>A | AT5: 1276 | AU5: ,A | AV5: intergenic_region | AW5: MODIFIER | AX5: CP01G000016-CP01G000017 | AY5: CP01G000016-CP01G000017 | AZ5: intergenic_region | BA5: CP01G000016-CP01G000017 | BB5: n.52322C>A
A6: 1 | B6: 73671 | C6: 1__73671 | D6: G | E6: =VLOOKUP(C6,significant_snps!#REF!,6,FALSE) -> #REF! | F6: ANN=A | G6: synonymous_variant | H6: LOW | I6: CP01G000031 | J6: cgd_1g300 | K6: CP01G000031 | L6: 40S ribosomal protein S21 | M6: CP01G000031.mRNA1 | N6: protein_coding | O6: 2/2 | P6: c.171C>T | Q6: p.Ala57Ala | R6: 171/249 | S6: 171/249 | T6: 57/82 | U6: ,A | V6: upstream_gene_variant | W6: MODIFIER | X6: CP01G000027 | Y6: CP01G000027 | Z6: transcript | AA6: CP01G000027.mRNA1 | AB6: protein_coding | AC6: c.-4118C>T | AD6: 4118 | AE6: ,A | AF6: upstream_gene_variant | AG6: MODIFIER | AH6: CP01G000029 | AI6: CP01G000029 | AJ6: transcript | AK6: CP01G000029.mRNA1 | AL6: protein_coding | AM6: c.-1803C>T | AN6: 1803 | AO6: ,A | AP6: downstream_gene_variant | AQ6: MODIFIER | AR6: CP01G000028 | AS6: CP01G000028 | AT6: transcript | AU6: CP01G000028.mRNA1 | AV6: protein_coding | AW6: c.*2947G>A | AX6: 2947 | AY6: ,A | AZ6: downstream_gene_variant | BA6: MODIFIER | BB6: CP01G000030 | BC6: CP01G000030 | BD6: transcript | BE6: CP01G000030.mRNA1 | BF6: protein_coding | BG6: c.*175G>A | BH6: 175 | BI6: ,A | BJ6: downstream_gene_variant | BK6: MODIFIER | BL6: CP01G000032 | BM6: CP01G000032 | BN6: transcript | BO6: CP01G000032.mRNA1 | BP6: protein_coding | BQ6: c.*602C>T | BR6: 602 | BS6: ,A | BT6: downstream_gene_variant | BU6: MODIFIER | BV6: CP01G000033 | BW6: CP01G000033 | BX6: transcript | BY6: CP01G000033.mRNA1 | BZ6: protein_coding | CA6: c.*1907C>T | CB6: 1907 | CC6: ,A | CD6: downstream_gene_variant | CE6: MODIFIER | CF6: CP01G000034 | CG6: CP01G000034 | CH6: transcript | CI6: CP01G000034.mRNA1 | CJ6: protein_coding | CK6: c.*4737C>T | CL6: 4737 | DB6: c.*1907C>T | DG6: 1907 | DH6: ,A | DI6: downstream_gene_variant | DJ6: MODIFIER | DK6: CP01G000034 | DL6: CP01G000034 | DM6: transcript | DN6: CP01G000034.mRNA1 | DO6: protein_coding | DQ6: c.*4737C>T | DV6: 4737
A7: 1 | B7: 74017 | C7: 1__74017 | D7: G | E7: =VLOOKUP(C7,significant_snps!#REF!,6,FALSE) -> #REF! | F7: ANN=A | G7: upstream_gene_variant | H7: MODIFIER | I7: CP01G000027 | J7: cgd_1g260 | K7: CP01G000027 | L7: putative signal peptide-containing secreted | M7: CP01G000027.mRNA1 | N7: protein_coding | O7: c.-4464C>T | P7: 4464 | Q7: ,A | R7: upstream_gene_variant | S7: MODIFIER | T7: CP01G000029 | U7: CP01G000029 | V7: transcript | W7: CP01G000029.mRNA1 | X7: protein_coding | Y7: c.-2149C>T | Z7: 2149 | AA7: ,A | AB7: upstream_gene_variant | AC7: MODIFIER | AD7: CP01G000031 | AE7: CP01G000031 | AF7: transcript | AG7: CP01G000031.mRNA1 | AH7: protein_coding | AI7: c.-81C>T | AJ7: 81 | AK7: ,A | AL7: downstream_gene_variant | AM7: MODIFIER | AN7: CP01G000028 | AO7: CP01G000028 | AP7: transcript | AQ7: CP01G000028.mRNA1 | AR7: protein_coding | AS7: c.*3293G>A | AT7: 3293 | AU7: ,A | AV7: downstream_gene_variant | AW7: MODIFIER | AX7: CP01G000030 | AY7: CP01G000030 | AZ7: transcript | BA7: CP01G000030.mRNA1 | BB7: protein_coding | BC7: c.*521G>A | BD7: 521 | BE7: ,A | BF7: downstream_gene_variant | BG7: MODIFIER | BH7: CP01G000032 | BI7: CP01G000032 | BJ7: transcript | BK7: CP01G000032.mRNA1 | BL7: protein_coding | BM7: c.*256C>T | BN7: 256 | BO7: ,A | BP7: downstream_gene_variant | BQ7: MODIFIER | BR7: CP01G000033 | BS7: CP01G000033 | BT7: transcript | BU7: CP01G000033.mRNA1 | BV7: protein_coding | BW7: c.*1561C>T | BX7: 1561 | BY7: ,A | BZ7: downstream_gene_variant | CA7: MODIFIER | CB7: CP01G000034 | CC7: CP01G000034 | CD7: transcript | CE7: CP01G000034.mRNA1 | CF7: protein_coding | CG7: c.*4391C>T | CH7: 4391 | CI7: ,A | CJ7: intergenic_region | CK7: MODIFIER | CL7: CP01G000031-CP01G000032 | CM7: CP01G000031-CP01G000032 | CN7: intergenic_region | CO7: CP01G000031-CP01G000032 | CP7: n.74017G>A | DB7: c.*1561C>T | DG7: 1561 | DH7: ,A | DI7: downstream_gene_variant | DJ7: MODIFIER | DK7: CP01G000034 | DL7: CP01G000034 | DM7: transcript | DN7: CP01G000034.mRNA1 | DO7: protein_coding | DQ7: c.*4391C>T | DV7: 4391 | DW7: ,A | DX7: intergenic_region | DY7: MODIFIER | DZ7: CP01G000031-CP01G000032 | EA7: CP01G000031-CP01G000032 | EB7: intergenic_region | EC7: CP01G000031-CP01G000032 | EF7: n.74017G>A
A8: 1 | B8: 82174 | C8: 1__82174 | D8: G | E8: =VLOOKUP(C8,significant_snps!#REF!,6,FALSE) -> #REF! | F8: ANN=A | G8: synonymous_variant | H8: LOW | I8: CP01G000035 | J8: cgd_1g340 | K8: CP01G000035 | L8: hypothetical protein | M8: CP01G000035.mRNA1 | N8: protein_coding | O8: 1/1 | P8: c.504G>A | Q8: p.Val168Val | R8: 504/1194 | S8: 504/1194 | T8: 168/397 | U8: ,A | V8: upstream_gene_variant | W8: MODIFIER | X8: CP01G000033 | Y8: CP01G000033 | Z8: transcript | AA8: CP01G000033.mRNA1 | AB8: protein_coding | AC8: c.-4848C>T | AD8: 4848 | AE8: ,A | AF8: upstream_gene_variant | AG8: MODIFIER | AH8: CP01G000034 | AI8: CP01G000034 | AJ8: transcript | AK8: CP01G000034.mRNA1 | AL8: protein_coding | AM8: c.-1322C>T | AN8: 1322 | AO8: ,A | AP8: upstream_gene_variant | AQ8: MODIFIER | AR8: CP01G000036 | AS8: CP01G000036 | AT8: transcript | AU8: CP01G000036.mRNA1 | AV8: protein_coding | AW8: c.-1343G>A | AX8: 1343 | AY8: ,A | AZ8: downstream_gene_variant | BA8: MODIFIER | BB8: CP01G000037 | BC8: CP01G000037 | BD8: transcript | BE8: CP01G000037.mRNA1 | BF8: protein_coding | BG8: c.*4536C>T | BH8: 4536
A9: 1 | B9: 83228 | C9: 1__83228 | D9: C | E9: =VLOOKUP(C9,significant_snps!#REF!,6,FALSE) -> #REF! | F9: ANN=A | G9: upstream_gene_variant | H9: MODIFIER | I9: CP01G000034 | J9: cgd_1g330 | K9: CP01G000034 | L9: CDC48-like AAA ATPase | M9: CP01G000034.mRNA1 | N9: protein_coding | O9: c.-2376G>T | P9: 2376 | Q9: ,A | R9: upstream_gene_variant | S9: MODIFIER | T9: CP01G000036 | U9: CP01G000036 | V9: transcript | W9: CP01G000036.mRNA1 | X9: protein_coding | Y9: c.-289C>A | Z9: 289 | AA9: ,A | AB9: downstream_gene_variant | AC9: MODIFIER | AD9: CP01G000035 | AE9: CP01G000035 | AF9: transcript | AG9: CP01G000035.mRNA1 | AH9: protein_coding | AI9: c.*364C>A | AJ9: 364 | AK9: ,A | AL9: downstream_gene_variant | AM9: MODIFIER | AN9: CP01G000037 | AO9: CP01G000037 | AP9: transcript | AQ9: CP01G000037.mRNA1 | AR9: protein_coding | AS9: c.*3482G>T | AT9: 3482 | AU9: ,A | AV9: intergenic_region | AW9: MODIFIER | AX9: CP01G000035-CP01G000036 | AY9: CP01G000035-CP01G000036 | AZ9: intergenic_region | BA9: CP01G000035-CP01G000036 | BB9: n.83228C>A
A10: 1 | B10: 83264 | C10: 1__83264 | D10: T | E10: =VLOOKUP(C10,significant_snps!#REF!,6,FALSE) -> #REF! | F10: ANN=C | G10: upstream_gene_variant | H10: MODIFIER | I10: CP01G000034 | J10: cgd_1g330 | K10: CP01G000034 | L10: CDC48-like AAA ATPase | M10: CP01G000034.mRNA1 | N10: protein_coding | O10: c.-2412A>G | P10: 2412 | Q10: ,C | R10: upstream_gene_variant | S10: MODIFIER | T10: CP01G000036 | U10: CP01G000036 | V10: transcript | W10: CP01G000036.mRNA1 | X10: protein_coding | Y10: c.-253T>C | Z10: 253 | AA10: ,C | AB10: downstream_gene_variant | AC10: MODIFIER | AD10: CP01G000035 | AE10: CP01G000035 | AF10: transcript | AG10: CP01G000035.mRNA1 | AH10: protein_coding | AI10: c.*400T>C | AJ10: 400 | AK10: ,C | AL10: downstream_gene_variant | AM10: MODIFIER | AN10: CP01G000037 | AO10: CP01G000037 | AP10: transcript | AQ10: CP01G000037.mRNA1 | AR10: protein_coding | AS10: c.*3446A>G | AT10: 3446 | AU10: ,C | AV10: intergenic_region | AW10: MODIFIER | AX10: CP01G000035-CP01G000036 | AY10: CP01G000035-CP01G000036 | AZ10: intergenic_region | BA10: CP01G000035-CP01G000036 | BB10: n.83264T>C
A11: 1 | B11: 84317 | C11: 1__84317 | D11: C | E11: =VLOOKUP(C11,significant_snps!#REF!,6,FALSE) -> #REF! | F11: ANN=T | G11: synonymous_variant | H11: LOW | I11: CP01G000036 | J11: cgd_1g350 | K11: CP01G000036 | L11: hypothetical protein | M11: CP01G000036.mRNA1 | N11: protein_coding | O11: 1/1 | P11: c.801C>T | Q11: p.Ser267Ser | R11: 801/1710 | S11: 801/1710 | T11: 267/569 | U11: ,T | V11: upstream_gene_variant | W11: MODIFIER | X11: CP01G000034 | Y11: CP01G000034 | Z11: transcript | AA11: CP01G000034.mRNA1 | AB11: protein_coding | AC11: c.-3465G>A | AD11: 3465 | AE11: ,T | AF11: downstream_gene_variant | AG11: MODIFIER | AH11: CP01G000035 | AI11: CP01G000035 | AJ11: transcript | AK11: CP01G000035.mRNA1 | AL11: protein_coding | AM11: c.*1453C>T | AN11: 1453 | AO11: ,T | AP11: downstream_gene_variant | AQ11: MODIFIER | AR11: CP01G000037 | AS11: CP01G000037 | AT11: transcript | AU11: CP01G000037.mRNA1 | AV11: protein_coding | AW11: c.*2393G>A | AX11: 2393
A12: 1 | B12: 85211 | C12: 1__85211 | D12: A | E12: =VLOOKUP(C12,significant_snps!#REF!,6,FALSE) -> #REF! | F12: ANN=G | G12: synonymous_variant | H12: LOW | I12: CP01G000036 | J12: cgd_1g350 | K12: CP01G000036 | L12: hypothetical protein | M12: CP01G000036.mRNA1 | N12: protein_coding | O12: 1/1 | P12: c.1695A>G | Q12: p.Pro565Pro | R12: 1695/1710 | S12: 1695/1710 | T12: 565/569 | U12: ,G | V12: upstream_gene_variant | W12: MODIFIER | X12: CP01G000034 | Y12: CP01G000034 | Z12: transcript | AA12: CP01G000034.mRNA1 | AB12: protein_coding | AC12: c.-4359T>C | AD12: 4359 | AE12: ,G | AF12: downstream_gene_variant | AG12: MODIFIER | AH12: CP01G000035 | AI12: CP01G000035 | AJ12: transcript | AK12: CP01G000035.mRNA1 | AL12: protein_coding | AM12: c.*2347A>G | AN12: 2347 | AO12: ,G | AP12: downstream_gene_variant | AQ12: MODIFIER | AR12: CP01G000037 | AS12: CP01G000037 | AT12: transcript | AU12: CP01G000037.mRNA1 | AV12: protein_coding | AW12: c.*1499T>C | AX12: 1499 | AY12: ,G | AZ12: downstream_gene_variant | BA12: MODIFIER | BB12: CP01G000038 | BC12: CP01G000038 | BD12: transcript | BE12: CP01G000038.mRNA1 | BF12: protein_coding | BG12: c.*4226T>C | BH12: 4226
A13: 1 | B13: 85278 | C13: 1__85278 | D13: A | E13: =VLOOKUP(C13,significant_snps!#REF!,6,FALSE) -> #REF! | F13: ANN=T | G13: upstream_gene_variant | H13: MODIFIER | I13: CP01G000034 | J13: cgd_1g330 | K13: CP01G000034 | L13: CDC48-like AAA ATPase | M13: CP01G000034.mRNA1 | N13: protein_coding | O13: c.-4426T>A | P13: 4426 | Q13: ,T | R13: downstream_gene_variant | S13: MODIFIER | T13: CP01G000035 | U13: CP01G000035 | V13: transcript | W13: CP01G000035.mRNA1 | X13: protein_coding | Y13: c.*2414A>T | Z13: 2414 | AA13: ,T | AB13: downstream_gene_variant | AC13: MODIFIER | AD13: CP01G000036 | AE13: CP01G000036 | AF13: transcript | AG13: CP01G000036.mRNA1 | AH13: protein_coding | AI13: c.*52A>T | AJ13: 52 | AK13: ,T | AL13: downstream_gene_variant | AM13: MODIFIER | AN13: CP01G000037 | AO13: CP01G000037 | AP13: transcript | AQ13: CP01G000037.mRNA1 | AR13: protein_coding | AS13: c.*1432T>A | AT13: 1432 | AU13: ,T | AV13: downstream_gene_variant | AW13: MODIFIER | AX13: CP01G000038 | AY13: CP01G000038 | AZ13: transcript | BA13: CP01G000038.mRNA1 | BB13: protein_coding | BC13: c.*4159T>A | BD13: 4159 | BE13: ,T | BF13: intergenic_region | BG13: MODIFIER | BH13: CP01G000036-CP01G000037 | BI13: CP01G000036-CP01G000037 | BJ13: intergenic_region | BK13: CP01G000036-CP01G000037 | BL13: n.85278A>T
A14: 1 | B14: 87126 | C14: 1__87126 | D14: T | E14: =VLOOKUP(C14,significant_snps!#REF!,6,FALSE) -> #REF! | F14: ANN=C | G14: missense_variant | H14: MODERATE | I14: CP01G000037 | J14: cgd_1g360 | K14: CP01G000037 | L14: hypothetical protein | M14: CP01G000037.mRNA1 | N14: protein_coding | O14: 1/1 | P14: c.2095A>G | Q14: p.Asn699Asp | R14: 2095/2511 | S14: 2095/2511 | T14: 699/836 | U14: ,C | V14: downstream_gene_variant | W14: MODIFIER | X14: CP01G000035 | Y14: CP01G000035 | Z14: transcript | AA14: CP01G000035.mRNA1 | AB14: protein_coding | AC14: c.*4262T>C | AD14: 4262 | AE14: ,C | AF14: downstream_gene_variant | AG14: MODIFIER | AH14: CP01G000036 | AI14: CP01G000036 | AJ14: transcript | AK14: CP01G000036.mRNA1 | AL14: protein_coding | AM14: c.*1900T>C | AN14: 1900 | AO14: ,C | AP14: downstream_gene_variant | AQ14: MODIFIER | AR14: CP01G000038 | AS14: CP01G000038 | AT14: transcript | AU14: CP01G000038.mRNA1 | AV14: protein_coding | AW14: c.*2311A>G | AX14: 2311
A15: 1 | B15: 107180 | C15: 1__107180 | D15: G | E15: =VLOOKUP(C15,significant_snps!#REF!,6,FALSE) -> #REF! | F15: ANN=A | G15: synonymous_variant | H15: LOW | I15: CP01G000048 | J15: cgd_1g470 | K15: CP01G000048 | L15: mucin-like protein | M15: CP01G000048.mRNA1 | N15: protein_coding | O15: 1/1 | P15: c.555G>A | Q15: p.Lys185Lys | R15: 555/2778 | S15: 555/2778 | T15: 185/925 | U15: ,A | V15: upstream_gene_variant | W15: MODIFIER | X15: CP01G000046 | Y15: CP01G000046 | Z15: transcript | AA15: CP01G000046.mRNA1 | AB15: protein_coding | AC15: c.-3760C>T | AD15: 3760 | AE15: ,A | AF15: upstream_gene_variant | AG15: MODIFIER | AH15: CP01G000047 | AI15: CP01G000047 | AJ15: transcript | AK15: CP01G000047.mRNA1 | AL15: protein_coding | AM15: c.-1613C>T | AN15: 1613 | AO15: ,A | AP15: downstream_gene_variant | AQ15: MODIFIER | AR15: CP01G000049 | AS15: CP01G000049 | AT15: transcript | AU15: CP01G000049.mRNA1 | AV15: protein_coding | AW15: c.*3375C>T | AX15: 3375 | AY15: ,A | AZ15: downstream_gene_variant | BA15: MODIFIER | BB15: CP01G000050 | BC15: CP01G000050 | BD15: transcript | BE15: CP01G000050.mRNA1 | BF15: protein_coding | BG15: c.*3872C>T | BH15: 3872
A16: 1 | B16: 109428 | C16: 1__109428 | D16: T | E16: =VLOOKUP(C16,significant_snps!#REF!,6,FALSE) -> #REF! | F16: ANN=A | G16: upstream_gene_variant | H16: MODIFIER | I16: CP01G000047 | J16: cgd_1g460 | K16: CP01G000047 | L16: hypothetical protein | M16: CP01G000047.mRNA1 | N16: protein_coding | O16: c.-3861A>T | P16: 3861 | Q16: ,A | R16: upstream_gene_variant | S16: MODIFIER | T16: CP01G000051 | U16: CP01G000051 | V16: transcript | W16: CP01G000051.mRNA1 | X16: protein_coding | Y16: c.-3749T>A | Z16: 3749 | AA16: ,A | AB16: downstream_gene_variant | AC16: MODIFIER | AD16: CP01G000048 | AE16: CP01G000048 | AF16: transcript | AG16: CP01G000048.mRNA1 | AH16: protein_coding | AI16: c.*25T>A | AJ16: 25 | AK16: ,A | AL16: downstream_gene_variant | AM16: MODIFIER | AN16: CP01G000049 | AO16: CP01G000049 | AP16: transcript | AQ16: CP01G000049.mRNA1 | AR16: protein_coding | AS16: c.*1127A>T | AT16: 1127 | AU16: ,A | AV16: downstream_gene_variant | AW16: MODIFIER | AX16: CP01G000050 | AY16: CP01G000050 | AZ16: transcript | BA16: CP01G000050.mRNA1 | BB16: protein_coding | BC16: c.*1624A>T | BD16: 1624 | BE16: ,A | BF16: intergenic_region | BG16: MODIFIER | BH16: CP01G000048-CP01G000049 | BI16: CP01G000048-CP01G000049 | BJ16: intergenic_region | BK16: CP01G000048-CP01G000049 | BL16: n.109428T>A
A17: 1 | B17: 132074 | C17: 1__132074 | D17: T | E17: =VLOOKUP(C17,significant_snps!#REF!,6,FALSE) -> #REF! | F17: ANN=A | G17: missense_variant | H17: MODERATE | I17: CP01G000058 | J17: cgd_1g560 | K17: CP01G000058 | L17: hypothetical protein | M17: CP01G000058.mRNA1 | N17: protein_coding | O17: 3/4 | P17: c.313T>A | Q17: p.Cys105Ser | R17: 313/1170 | S17: 313/1170 | T17: 105/389 | U17: ,A | V17: downstream_gene_variant | W17: MODIFIER | X17: CP01G000057 | Y17: CP01G000057 | Z17: transcript | AA17: CP01G000057.mRNA1 | AB17: protein_coding | AC17: c.*899T>A | AD17: 899 | AE17: ,A | AF17: downstream_gene_variant | AG17: MODIFIER | AH17: CP01G000059 | AI17: CP01G000059 | AJ17: transcript | AK17: CP01G000059.mRNA1 | AL17: protein_coding | AM17: c.*1105A>T | AN17: 1105 | AO17: ,A | AP17: downstream_gene_variant | AQ17: MODIFIER | AR17: CP01G000060 | AS17: CP01G000060 | AT17: transcript | AU17: CP01G000060.mRNA1 | AV17: protein_coding | AW17: c.*3350A>T | AX17: 3350
A18: 1 | B18: 136286 | C18: 1__136286 | D18: G | E18: =VLOOKUP(C18,significant_snps!#REF!,6,FALSE) -> #REF! | F18: ANN=A | G18: missense_variant | H18: MODERATE | I18: CP01G000060 | J18: cgd_1g580 | K18: CP01G000060 | L18: dynamin-like protein | M18: CP01G000060.mRNA1 | N18: protein_coding | O18: 2/2 | P18: c.1592C>T | Q18: p.Ala531Val | R18: 1592/2454 | S18: 1592/2454 | T18: 531/817 | U18: ,A | V18: upstream_gene_variant | W18: MODIFIER | X18: CP01G000059 | Y18: CP01G000059 | Z18: transcript | AA18: CP01G000059.mRNA1 | AB18: protein_coding | AC18: c.-2403C>T | AD18: 2403 | AE18: ,A | AF18: downstream_gene_variant | AG18: MODIFIER | AH18: CP01G000058 | AI18: CP01G000058 | AJ18: transcript | AK18: CP01G000058.mRNA1 | AL18: protein_coding | AM18: c.*3299G>A | AN18: 3299 | AO18: ,A | AP18: downstream_gene_variant | AQ18: MODIFIER | AR18: CP01G000061 | AS18: CP01G000061 | AT18: transcript | AU18: CP01G000061.mRNA1 | AV18: protein_coding | AW18: c.*2780C>T | AX18: 2780
A19: 1 | B19: 303924 | C19: 1__303924 | D19: C | E19: =VLOOKUP(C19,significant_snps!#REF!,6,FALSE) -> #REF! | F19: ANN=T | G19: upstream_gene_variant | H19: MODIFIER | I19: CP01G000127 | J19: cgd_1g1230 | K19: CP01G000127 | L19: putative signal peptide-containing secreted | M19: CP01G000127.mRNA1 | N19: protein_coding | O19: c.-75G>A | P19: 75 | Q19: ,T | R19: upstream_gene_variant | S19: MODIFIER | T19: CP01G000129 | U19: CP01G000129 | V19: transcript | W19: CP01G000129.mRNA1 | X19: protein_coding | Y19: c.-2452C>T | Z19: 2452 | AA19: ,T | AB19: downstream_gene_variant | AC19: MODIFIER | AD19: CP01G000126 | AE19: CP01G000126 | AF19: transcript | AG19: CP01G000126.mRNA1 | AH19: protein_coding | AI19: c.*3477C>T | AJ19: 3477 | AK19: ,T | AL19: downstream_gene_variant | AM19: MODIFIER | AN19: CP01G000128 | AO19: CP01G000128 | AP19: transcript | AQ19: CP01G000128.mRNA1 | AR19: protein_coding | AS19: c.*537G>A | AT19: 537 | AU19: ,T | AV19: intergenic_region | AW19: MODIFIER | AX19: CP01G000127-CP01G000128 | AY19: CP01G000127-CP01G000128 | AZ19: intergenic_region | BA19: CP01G000127-CP01G000128 | BB19: n.303924C>T
A20: 1 | B20: 698027 | C20: 1__698027 | D20: C | E20: =VLOOKUP(C20,significant_snps!#REF!,6,FALSE) -> #REF! | F20: ANN=A | G20: missense_variant | H20: MODERATE | I20: CP01G000325 | J20: cgd_1g3160 | K20: CP01G000325 | L20: mRNA 3' end processing protein RNA14 | M20: CP01G000325.mRNA1 | N20: protein_coding | O20: 1/1 | P20: c.3044C>A | Q20: p.Thr1015Asn | R20: 3044/4356 | S20: 3044/4356 | T20: 1015/1451 | U20: ,A | V20: upstream_gene_variant | W20: MODIFIER | X20: CP01G000324 | Y20: CP01G000324 | Z20: transcript | AA20: CP01G000324.mRNA1 | AB20: protein_coding | AC20: c.-4538G>T | AD20: 4538 | AE20: ,A | AF20: downstream_gene_variant | AG20: MODIFIER | AH20: CP01G000326 | AI20: CP01G000326 | AJ20: transcript | AK20: CP01G000326.mRNA1 | AL20: protein_coding | AM20: c.*1514G>T | AN20: 1514
A21: 1 | B21: 715530 | C21: 1__715530 | D21: T | E21: =VLOOKUP(C21,significant_snps!#REF!,6,FALSE) -> #REF! | F21: ANN=C | G21: missense_variant | H21: MODERATE | I21: CP01G000331 | J21: cgd_1g3220 | K21: CP01G000331 | L21: erythrocyte membrane-associated antigen | M21: CP01G000331.mRNA1 | N21: protein_coding | O21: 1/1 | P21: c.1849A>G | Q21: p.Ser617Gly | R21: 1849/2022 | S21: 1849/2022 | T21: 617/673 | U21: ,C | V21: upstream_gene_variant | W21: MODIFIER | X21: CP01G000332 | Y21: CP01G000332 | Z21: transcript | AA21: CP01G000332.mRNA1 | AB21: protein_coding | AC21: c.-3475T>C | AD21: 3475 | AE21: ,C | AF21: downstream_gene_variant | AG21: MODIFIER | AH21: CP01G000330 | AI21: CP01G000330 | AJ21: transcript | AK21: CP01G000330.mRNA1 | AL21: protein_coding | AM21: c.*791T>C | AN21: 791
A22: 1 | B22: 732150 | C22: 1__732150 | D22: G | E22: =VLOOKUP(C22,significant_snps!#REF!,6,FALSE) -> #REF! | F22: ANN=A | G22: missense_variant | H22: MODERATE | I22: CP01G000334 | J22: cgd_1g3250 | K22: CP01G000334 | L22: hypothetical protein | M22: CP01G000334.mRNA1 | N22: protein_coding | O22: 1/1 | P22: c.291G>A | Q22: p.Met97Ile | R22: 291/726 | S22: 291/726 | T22: 97/241 | U22: ,A | V22: upstream_gene_variant | W22: MODIFIER | X22: CP01G000333 | Y22: CP01G000333 | Z22: transcript | AA22: CP01G000333.mRNA1 | AB22: protein_coding | AC22: c.-787C>T | AD22: 787 | AE22: ,A | AF22: upstream_gene_variant | AG22: MODIFIER | AH22: CP01G000337 | AI22: CP01G000337 | AJ22: transcript | AK22: CP01G000337.mRNA1 | AL22: protein_coding | AM22: c.-4269G>A | AN22: 4269 | AO22: ,A | AP22: downstream_gene_variant | AQ22: MODIFIER | AR22: CP01G000335 | AS22: CP01G000335 | AT22: transcript | AU22: CP01G000335.mRNA1 | AV22: protein_coding | AW22: c.*838C>T | AX22: 838 | AY22: ,A | AZ22: downstream_gene_variant | BA22: MODIFIER | BB22: CP01G000336 | BC22: CP01G000336 | BD22: transcript | BE22: CP01G000336.mRNA1 | BF22: protein_coding | BG22: c.*2284C>T | BH22: 2284
A23: 1 | B23: 755389 | C23: 1__755389 | D23: A | E23: =VLOOKUP(C23,significant_snps!#REF!,6,FALSE) -> #REF! | F23: ANN=G | G23: upstream_gene_variant | H23: MODIFIER | I23: CP01G000347 | J23: cgd_1g3360 | K23: CP01G000347 | L23: putative AFG1 ATPase-like AAA ATPase | M23: CP01G000347.mRNA1 | N23: protein_coding | O23: c.-3060T>C | P23: 3060 | Q23: ,G | R23: upstream_gene_variant | S23: MODIFIER | T23: CP01G000349 | U23: CP01G000349 | V23: transcript | W23: CP01G000349.mRNA1 | X23: protein_coding | Y23: c.-1033T>C | Z23: 1033 | AA23: ,G | AB23: upstream_gene_variant | AC23: MODIFIER | AD23: CP01G000351 | AE23: CP01G000351 | AF23: transcript | AG23: CP01G000351.mRNA1 | AH23: protein_coding | AI23: c.-1984A>G | AJ23: 1984 | AK23: ,G | AL23: upstream_gene_variant | AM23: MODIFIER | AN23: CP01G000352 | AO23: CP01G000352 | AP23: transcript | AQ23: CP01G000352.mRNA1 | AR23: protein_coding | AS23: c.-3542A>G | AT23: 3542 | AU23: ,G | AV23: upstream_gene_variant | AW23: MODIFIER | AX23: CP01G000353 | AY23: CP01G000353 | AZ23: transcript | BA23: CP01G000353.mRNA1 | BB23: protein_coding | BC23: c.-4810A>G | BD23: 4810 | BE23: ,G | BF23: downstream_gene_variant | BG23: MODIFIER | BH23: CP01G000348 | BI23: CP01G000348 | BJ23: transcript | BK23: CP01G000348.mRNA1 | BL23: protein_coding | BM23: c.*1988A>G | BN23: 1988 | BO23: ,G | BP23: downstream_gene_variant | BQ23: MODIFIER | BR23: CP01G000350 | BS23: CP01G000350 | BT23: transcript | BU23: CP01G000350.mRNA1 | BV23: protein_coding | BW23: c.*181T>C | BX23: 181 | BY23: ,G | BZ23: intergenic_region | CA23: MODIFIER | CB23: CP01G000349-CP01G000350 | CC23: CP01G000349-CP01G000350 | CD23: intergenic_region | CE23: CP01G000349-CP01G000350 | CF23: n.755389A>G | DB23: c.*181T>C | DG23: 181 | DH23: ,G | DI23: intergenic_region | DJ23: MODIFIER | DK23: CP01G000349-CP01G000350 | DL23: CP01G000349-CP01G000350 | DM23: intergenic_region | DN23: CP01G000349-CP01G000350 | DQ23: n.755389A>G
A24: 1 | B24: 758101 | C24: 1__758101 | D24: A | E24: =VLOOKUP(C24,significant_snps!#REF!,6,FALSE) -> #REF! | F24: ANN=T | G24: synonymous_variant | H24: LOW | I24: CP01G000351 | J24: cgd_1g3400 | K24: CP01G000351 | L24: hypothetical protein | M24: CP01G000351.mRNA1 | N24: protein_coding | O24: 1/1 | P24: c.729A>T | Q24: p.Thr243Thr | R24: 729/1152 | S24: 729/1152 | T24: 243/383 | U24: ,T | V24: upstream_gene_variant | W24: MODIFIER | X24: CP01G000349 | Y24: CP01G000349 | Z24: transcript | AA24: CP01G000349.mRNA1 | AB24: protein_coding | AC24: c.-3745T>A | AD24: 3745 | AE24: ,T | AF24: upstream_gene_variant | AG24: MODIFIER | AH24: CP01G000350 | AI24: CP01G000350 | AJ24: transcript | AK24: CP01G000350.mRNA1 | AL24: protein_coding | AM24: c.-1149T>A | AN24: 1149 | AO24: ,T | AP24: upstream_gene_variant | AQ24: MODIFIER | AR24: CP01G000352 | AS24: CP01G000352 | AT24: transcript | AU24: CP01G000352.mRNA1 | AV24: protein_coding | AW24: c.-830A>T | AX24: 830 | AY24: ,T | AZ24: upstream_gene_variant | BA24: MODIFIER | BB24: CP01G000353 | BC24: CP01G000353 | BD24: transcript | BE24: CP01G000353.mRNA1 | BF24: protein_coding | BG24: c.-2098A>T | BH24: 2098 | BI24: ,T | BJ24: upstream_gene_variant | BK24: MODIFIER | BL24: CP01G000354 | BM24: CP01G000354 | BN24: transcript | BO24: CP01G000354.mRNA1 | BP24: protein_coding | BQ24: c.-4378A>T | BR24: 4378 | BS24: ,T | BT24: downstream_gene_variant | BU24: MODIFIER | BV24: CP01G000348 | BW24: CP01G000348 | BX24: transcript | BY24: CP01G000348.mRNA1 | BZ24: protein_coding | CA24: c.*4700A>T | CB24: 4700 | CC24: ,T | CD24: downstream_gene_variant | CE24: MODIFIER | CF24: CP01G000355 | CG24: CP01G000355 | CH24: transcript | CI24: CP01G000355.mRNA1 | CJ24: protein_coding | CK24: c.*4877T>A | CL24: 4877 | DB24: c.*4700A>T | DG24: 4700 | DH24: ,T | DI24: downstream_gene_variant | DJ24: MODIFIER | DK24: CP01G000355 | DL24: CP01G000355 | DM24: transcript | DN24: CP01G000355.mRNA1 | DO24: protein_coding | DQ24: c.*4877T>A | DV24: 4877
A25: 1 | B25: 773113 | C25: 1__773113 | D25: C | E25: =VLOOKUP(C25,significant_snps!#REF!,6,FALSE) -> #REF! | F25: ANN=A | G25: upstream_gene_variant | H25: MODIFIER | I25: CP01G000357 | J25: cgd_1g3460 | K25: CP01G000357 | L25: F-actin capping protein beta subunit | M25: CP01G000357.mRNA1 | N25: protein_coding | O25: c.-4967G>T | P25: 4967 | Q25: ,A | R25: upstream_gene_variant | S25: MODIFIER | T25: CP01G000359 | U25: CP01G000359 | V25: transcript | W25: CP01G000359.mRNA1 | X25: protein_coding | Y25: c.-2209G>T | Z25: 2209 | AA25: ,A | AB25: upstream_gene_variant | AC25: MODIFIER | AD25: CP01G000360 | AE25: CP01G000360 | AF25: transcript | AG25: CP01G000360.mRNA1 | AH25: protein_coding | AI25: c.-917G>T | AJ25: 917 | AK25: ,A | AL25: upstream_gene_variant | AM25: MODIFIER | AN25: CP01G000362 | AO25: CP01G000362 | AP25: transcript | AQ25: CP01G000362.mRNA1 | AR25: protein_coding | AS25: c.-2943C>A | AT25: 2943 | AU25: ,A | AV25: downstream_gene_variant | AW25: MODIFIER | AX25: CP01G000358 | AY25: CP01G000358 | AZ25: transcript | BA25: CP01G000358.mRNA1 | BB25: protein_coding | BC25: c.*3729C>A | BD25: 3729 | BE25: ,A | BF25: downstream_gene_variant | BG25: MODIFIER | BH25: CP01G000361 | BI25: CP01G000361 | BJ25: transcript | BK25: CP01G000361.mRNA1 | BL25: protein_coding | BM25: c.*101G>T | BN25: 101 | BO25: ,A | BP25: intergenic_region | BQ25: MODIFIER | BR25: CP01G000360-CP01G000361 | BS25: CP01G000360-CP01G000361 | BT25: intergenic_region | BU25: CP01G000360-CP01G000361 | BV25: n.773113C>A | DB25: n.773113C>A
A26: 1 | B26: 807015 | C26: 1__807015 | D26: C | E26: =VLOOKUP(C26,significant_snps!#REF!,6,FALSE) -> #REF! | F26: ANN=T | G26: upstream_gene_variant | H26: MODIFIER | I26: CP01G000374 | J26: cgd_1g3620 | K26: CP01G000374 | L26: TAFII55 | M26: CP01G000374.mRNA1 | N26: protein_coding | O26: c.-4108C>T | P26: 4108 | Q26: ,T | R26: downstream_gene_variant | S26: MODIFIER | T26: CP01G000371 | U26: CP01G000371 | V26: transcript | W26: CP01G000371.mRNA1 | X26: protein_coding | Y26: c.*3216C>T | Z26: 3216 | AA26: ,T | AB26: downstream_gene_variant | AC26: MODIFIER | AD26: CP01G000372 | AE26: CP01G000372 | AF26: transcript | AG26: CP01G000372.mRNA1 | AH26: protein_coding | AI26: c.*115C>T | AJ26: 115 | AK26: ,T | AL26: downstream_gene_variant | AM26: MODIFIER | AN26: CP01G000373 | AO26: CP01G000373 | AP26: transcript | AQ26: CP01G000373.mRNA1 | AR26: protein_coding | AS26: c.*92G>A | AT26: 92 | AU26: ,T | AV26: intergenic_region | AW26: MODIFIER | AX26: CP01G000372-CP01G000373 | AY26: CP01G000372-CP01G000373 | AZ26: intergenic_region | BA26: CP01G000372-CP01G000373 | BB26: n.807015C>T
A27: 1 | B27: 814587 | C27: 1__814587 | D27: T | E27: =VLOOKUP(C27,significant_snps!#REF!,6,FALSE) -> #REF! | F27: ANN=C | G27: missense_variant | H27: MODERATE | I27: CP01G000375 | J27: cgd_1g3630 | K27: CP01G000375 | L27: hypothetical protein | M27: CP01G000375.mRNA1 | N27: protein_coding | O27: 1/1 | P27: c.244A>G | Q27: p.Ser82Gly | R27: 244/2220 | S27: 244/2220 | T27: 82/739 | U27: ,C | V27: upstream_gene_variant | W27: MODIFIER | X27: CP01G000373 | Y27: CP01G000373 | Z27: transcript | AA27: CP01G000373.mRNA1 | AB27: protein_coding | AC27: c.-4673A>G | AD27: 4673 | AE27: ,C | AF27: upstream_gene_variant | AG27: MODIFIER | AH27: CP01G000376 | AI27: CP01G000376 | AJ27: transcript | AK27: CP01G000376.mRNA1 | AL27: protein_coding | AM27: c.-686T>C | AN27: 686 | AO27: ,C | AP27: downstream_gene_variant | AQ27: MODIFIER | AR27: CP01G000374 | AS27: CP01G000374 | AT27: transcript | AU27: CP01G000374.mRNA1 | AV27: protein_coding | AW27: c.*2358T>C | AX27: 2358 | AY27: ,C | AZ27: downstream_gene_variant | BA27: MODIFIER | BB27: CP01G000377 | BC27: CP01G000377 | BD27: transcript | BE27: CP01G000377.mRNA1 | BF27: protein_coding | BG27: c.*3016A>G | BH27: 3016 | BI27: ,C | BJ27: downstream_gene_variant | BK27: MODIFIER | BL27: CP01G000378 | BM27: CP01G000378 | BN27: transcript | BO27: CP01G000378.mRNA1 | BP27: protein_coding | BQ27: c.*4375A>G | BR27: 4375
A28: 1 | B28: 844126 | C28: 1__844126 | D28: C | E28: =VLOOKUP(C28,significant_snps!#REF!,6,FALSE) -> #REF! | F28: ANN=T | G28: synonymous_variant | H28: LOW | I28: CP01G000386 | J28: cgd_1g3740 | K28: CP01G000386 | L28: ankyrin repeat protein | M28: CP01G000386.mRNA1 | N28: protein_coding | O28: 1/1 | P28: c.1773C>T | Q28: p.Ala591Ala | R28: 1773/4224 | S28: 1773/4224 | T28: 591/1407 | U28: ,T | V28: upstream_gene_variant | W28: MODIFIER | X28: CP01G000385 | Y28: CP01G000385 | Z28: transcript | AA28: CP01G000385.mRNA1 | AB28: protein_coding | AC28: c.-2176G>A | AD28: 2176 | AE28: ,T | AF28: upstream_gene_variant | AG28: MODIFIER | AH28: CP01G000388 | AI28: CP01G000388 | AJ28: transcript | AK28: CP01G000388.mRNA1 | AL28: protein_coding | AM28: c.-3757C>T | AN28: 3757 | AO28: ,T | AP28: downstream_gene_variant | AQ28: MODIFIER | AR28: CP01G000384 | AS28: CP01G000384 | AT28: transcript | AU28: CP01G000384.mRNA1 | AV28: protein_coding | AW28: c.*4835C>T | AX28: 4835 | AY28: ,T | AZ28: downstream_gene_variant | BA28: MODIFIER | BB28: CP01G000387 | BC28: CP01G000387 | BD28: transcript | BE28: CP01G000387.mRNA1 | BF28: protein_coding | BG28: c.*2698G>A | BH28: 2698
A29: 1 | B29: 855001 | C29: 1__855001 | D29: C | E29: =VLOOKUP(C29,significant_snps!#REF!,6,FALSE) -> #REF! | F29: ANN=T | G29: upstream_gene_variant | H29: MODIFIER | I29: CP01G000390 | J29: cgd_1g3780 | K29: CP01G000390 | L29: ATRX, DEAD-box-like | M29: CP01G000390.mRNA1 | N29: protein_coding | O29: c.-114G>A | P29: 114 | Q29: ,T | R29: upstream_gene_variant | S29: MODIFIER | T29: CP01G000392 | U29: CP01G000392 | V29: transcript | W29: CP01G000392.mRNA1 | X29: protein_coding | Y29: c.-4662C>T | Z29: 4662 | AA29: ,T | AB29: downstream_gene_variant | AC29: MODIFIER | AD29: CP01G000388 | AE29: CP01G000388 | AF29: transcript | AG29: CP01G000388.mRNA1 | AH29: protein_coding | AI29: c.*3639C>T | AJ29: 3639 | AK29: ,T | AL29: downstream_gene_variant | AM29: MODIFIER | AN29: CP01G000389 | AO29: CP01G000389 | AP29: transcript | AQ29: CP01G000389.mRNA1 | AR29: protein_coding | AS29: c.*2681C>T | AT29: 2681 | AU29: ,T | AV29: downstream_gene_variant | AW29: MODIFIER | AX29: CP01G000391 | AY29: CP01G000391 | AZ29: transcript | BA29: CP01G000391.mRNA1 | BB29: protein_coding | BC29: c.*62G>A | BD29: 62 | BE29: ,T | BF29: intergenic_region | BG29: MODIFIER | BH29: CP01G000390-CP01G000391 | BI29: CP01G000390-CP01G000391 | BJ29: intergenic_region | BK29: CP01G000390-CP01G000391 | BL29: n.855001C>T
A30: 2 | B30: 23546 | C30: 2__23546 | D30: T | E30: =VLOOKUP(C30,significant_snps!#REF!,6,FALSE) -> #REF! | F30: ANN=A | G30: missense_variant | H30: MODERATE | I30: CP02G000013 | J30: cgd_2g340 | K30: CP02G000013 | L30: signal peptide-containing protein | M30: CP02G000013.mRNA1 | N30: protein_coding | O30: 1/1 | P30: c.2962A>T | Q30: p.Arg988Trp | R30: 2962/3711 | S30: 2962/3711 | T30: 988/1236 | U30: ,A | V30: downstream_gene_variant | W30: MODIFIER | X30: CP02G000010 | Y30: CP02G000010 | Z30: transcript | AA30: CP02G000010.mRNA1 | AB30: protein_coding | AC30: c.*4445T>A | AD30: 4445 | AE30: ,A | AF30: downstream_gene_variant | AG30: MODIFIER | AH30: CP02G000011 | AI30: CP02G000011 | AJ30: transcript | AK30: CP02G000011.mRNA1 | AL30: protein_coding | AM30: c.*1615T>A | AN30: 1615 | AO30: ,A | AP30: downstream_gene_variant | AQ30: MODIFIER | AR30: CP02G000012 | AS30: CP02G000012 | AT30: transcript | AU30: CP02G000012.mRNA1 | AV30: protein_coding | AW30: c.*996T>A | AX30: 996 | AY30: ,A | AZ30: downstream_gene_variant | BA30: MODIFIER | BB30: CP02G000014 | BC30: CP02G000014 | BD30: transcript | BE30: CP02G000014.mRNA1 | BF30: protein_coding | BG30: c.*3476A>T | BH30: 3476
A31: 2 | B31: 23946 | C31: 2__23946 | D31: T | E31: =VLOOKUP(C31,significant_snps!#REF!,6,FALSE) -> #REF! | F31: ANN=C | G31: synonymous_variant | H31: LOW | I31: CP02G000013 | J31: cgd_2g340 | K31: CP02G000013 | L31: signal peptide-containing protein | M31: CP02G000013.mRNA1 | N31: protein_coding | O31: 1/1 | P31: c.2562A>G | Q31: p.Glu854Glu | R31: 2562/3711 | S31: 2562/3711 | T31: 854/1236 | U31: ,C | V31: upstream_gene_variant | W31: MODIFIER | X31: CP02G000015 | Y31: CP02G000015 | Z31: transcript | AA31: CP02G000015.mRNA1 | AB31: protein_coding | AC31: c.-4868T>C | AD31: 4868 | AE31: ,C | AF31: downstream_gene_variant | AG31: MODIFIER | AH31: CP02G000010 | AI31: CP02G000010 | AJ31: transcript | AK31: CP02G000010.mRNA1 | AL31: protein_coding | AM31: c.*4845T>C | AN31: 4845 | AO31: ,C | AP31: downstream_gene_variant | AQ31: MODIFIER | AR31: CP02G000011 | AS31: CP02G000011 | AT31: transcript | AU31: CP02G000011.mRNA1 | AV31: protein_coding | AW31: c.*2015T>C | AX31: 2015 | AY31: ,C | AZ31: downstream_gene_variant | BA31: MODIFIER | BB31: CP02G000012 | BC31: CP02G000012 | BD31: transcript | BE31: CP02G000012.mRNA1 | BF31: protein_coding | BG31: c.*1396T>C | BH31: 1396 | BI31: ,C | BJ31: downstream_gene_variant | BK31: MODIFIER | BL31: CP02G000014 | BM31: CP02G000014 | BN31: transcript | BO31: CP02G000014.mRNA1 | BP31: protein_coding | BQ31: c.*3076A>G | BR31: 3076
A32: 2 | B32: 40644 | C32: 2__40644 | D32: C | E32: =VLOOKUP(C32,significant_snps!#REF!,6,FALSE) -> #REF! | F32: ANN=T | G32: missense_variant | H32: MODERATE | I32: CP02G000021 | J32: cgd_2g260 | K32: CP02G000021 | L32: hypothetical protein | M32: CP02G000021.mRNA1 | N32: protein_coding | O32: 1/1 | P32: c.636G>A | Q32: p.Met212Ile | R32: 636/657 | S32: 636/657 | T32: 212/218 | U32: ,T | V32: upstream_gene_variant | W32: MODIFIER | X32: CP02G000019 | Y32: CP02G000019 | Z32: transcript | AA32: CP02G000019.mRNA1 | AB32: protein_coding | AC32: c.-2607G>A | AD32: 2607 | AE32: ,T | AF32: upstream_gene_variant | AG32: MODIFIER | AH32: CP02G000020 | AI32: CP02G000020 | AJ32: transcript | AK32: CP02G000020.mRNA1 | AL32: protein_coding | AM32: c.-452G>A | AN32: 452 | AO32: ,T | AP32: upstream_gene_variant | AQ32: MODIFIER | AR32: CP02G000022 | AS32: CP02G000022 | AT32: transcript | AU32: CP02G000022.mRNA1 | AV32: protein_coding | AW32: c.-1294C>T | AX32: 1294 | AY32: ,T | AZ32: downstream_gene_variant | BA32: MODIFIER | BB32: CP02G000018 | BC32: CP02G000018 | BD32: transcript | BE32: CP02G000018.mRNA1 | BF32: protein_coding | BG32: c.*3353C>T | BH32: 3353 | BI32: ,T | BJ32: downstream_gene_variant | BK32: MODIFIER | BL32: CP02G000023 | BM32: CP02G000023 | BN32: transcript | BO32: CP02G000023.mRNA1 | BP32: protein_coding | BQ32: c.*1806G>A | BR32: 1806 | BS32: ,T | BT32: downstream_gene_variant | BU32: MODIFIER | BV32: CP02G000024 | BW32: CP02G000024 | BX32: transcript | BY32: CP02G000024.mRNA1 | BZ32: protein_coding | CA32: c.*3612G>A | CB32: 3612 | DB32: c.*3612G>A | DG32: 3612
A33: 2 | B33: 41909 | C33: 2__41909 | D33: A | E33: =VLOOKUP(C33,significant_snps!#REF!,6,FALSE) -> #REF! | F33: ANN=C | G33: upstream_gene_variant | H33: MODIFIER | I33: CP02G000019 | J33: cgd_2g280 | K33: CP02G000019 | L33: 60S ribosomal protein L15 | M33: CP02G000019.mRNA1 | N33: protein_coding | O33: c.-3872T>G | P33: 3872 | Q33: ,C | R33: upstream_gene_variant | S33: MODIFIER | T33: CP02G000020 | U33: CP02G000020 | V33: transcript | W33: CP02G000020.mRNA1 | X33: protein_coding | Y33: c.-1717T>G | Z33: 1717 | AA33: ,C | AB33: upstream_gene_variant | AC33: MODIFIER | AD33: CP02G000021 | AE33: CP02G000021 | AF33: transcript | AG33: CP02G000021.mRNA1 | AH33: protein_coding | AI33: c.-630T>G | AJ33: 630 | AK33: ,C | AL33: upstream_gene_variant | AM33: MODIFIER | AN33: CP02G000022 | AO33: CP02G000022 | AP33: transcript | AQ33: CP02G000022.mRNA1 | AR33: protein_coding | AS33: c.-29A>C | AT33: 29 | AU33: ,C | AV33: downstream_gene_variant | AW33: MODIFIER | AX33: CP02G000018 | AY33: CP02G000018 | AZ33: transcript | BA33: CP02G000018.mRNA1 | BB33: protein_coding | BC33: c.*4618A>C | BD33: 4618 | BE33: ,C | BF33: downstream_gene_variant | BG33: MODIFIER | BH33: CP02G000023 | BI33: CP02G000023 | BJ33: transcript | BK33: CP02G000023.mRNA1 | BL33: protein_coding | BM33: c.*541T>G | BN33: 541 | BO33: ,C | BP33: downstream_gene_variant | BQ33: MODIFIER | BR33: CP02G000024 | BS33: CP02G000024 | BT33: transcript | BU33: CP02G000024.mRNA1 | BV33: protein_coding | BW33: c.*2347T>G | BX33: 2347 | BY33: ,C | BZ33: intergenic_region | CA33: MODIFIER | CB33: CP02G000021-CP02G000022 | CC33: CP02G000021-CP02G000022 | CD33: intergenic_region | CE33: CP02G000021-CP02G000022 | CF33: n.41909A>C | DB33: c.*2347T>G | DG33: 2347 | DH33: ,C | DI33: intergenic_region | DJ33: MODIFIER | DK33: CP02G000021-CP02G000022 | DL33: CP02G000021-CP02G000022 | DM33: intergenic_region | DN33: CP02G000021-CP02G000022 | DQ33: n.41909A>C
A34: 2 | B34: 55683 | C34: 2__55683 | D34: A | E34: =VLOOKUP(C34,significant_snps!#REF!,6,FALSE) -> #REF! | F34: ANN=G | G34: upstream_gene_variant | H34: MODIFIER | I34: CP02G000025 | J34: cgd_2g220 | K34: CP02G000025 | L34: transcription factor TFIIF | M34: CP02G000025.mRNA1 | N34: protein_coding | O34: c.-4733T>C | P34: 4733 | Q34: ,G | R34: upstream_gene_variant | S34: MODIFIER | T34: CP02G000028 | U34: CP02G000028 | V34: transcript | W34: CP02G000028.mRNA1 | X34: protein_coding | Y34: c.-504T>C | Z34: 504 | AA34: ,G | AB34: upstream_gene_variant | AC34: MODIFIER | AD34: CP02G000029 | AE34: CP02G000029 | AF34: transcript | AG34: CP02G000029.mRNA1 | AH34: protein_coding | AI34: c.-267A>G | AJ34: 267 | AK34: ,G | AL34: upstream_gene_variant | AM34: MODIFIER | AN34: CP02G000031 | AO34: CP02G000031 | AP34: transcript | AQ34: CP02G000031.mRNA1 | AR34: protein_coding | AS34: c.-2319A>G | AT34: 2319 | AU34: ,G | AV34: upstream_gene_variant | AW34: MODIFIER | AX34: CP02G000032 | AY34: CP02G000032 | AZ34: transcript | BA34: CP02G000032.mRNA1 | BB34: protein_coding | BC34: c.-4207A>G | BD34: 4207 | BE34: ,G | BF34: downstream_gene_variant | BG34: MODIFIER | BH34: CP02G000026 | BI34: CP02G000026 | BJ34: transcript | BK34: CP02G000026.mRNA1 | BL34: protein_coding | BM34: c.*2646A>G | BN34: 2646 | BO34: ,G | BP34: downstream_gene_variant | BQ34: MODIFIER | BR34: CP02G000027 | BS34: CP02G000027 | BT34: transcript | BU34: CP02G000027.mRNA1 | BV34: protein_coding | BW34: c.*1104A>G | BX34: 1104 | BY34: ,G | BZ34: downstream_gene_variant | CA34: MODIFIER | CB34: CP02G000030 | CC34: CP02G000030 | CD34: transcript | CE34: CP02G000030.mRNA1 | CF34: protein_coding | CG34: c.*1241T>C | CH34: 1241 | CI34: ,G | CJ34: intergenic_region | CK34: MODIFIER | CL34: CP02G000028-CP02G000029 | CM34: CP02G000028-CP02G000029 | CN34: intergenic_region | CO34: CP02G000028-CP02G000029 | CP34: n.55683A>G | DB34: c.*1104A>G | DG34: 1104 | DH34: ,G | DI34: downstream_gene_variant | DJ34: MODIFIER | DK34: CP02G000030 | DL34: CP02G000030 | DM34: transcript | DN34: CP02G000030.mRNA1 | DO34: protein_coding | DQ34: c.*1241T>C | DV34: 1241 | DW34: ,G | DX34: intergenic_region | DY34: MODIFIER | DZ34: CP02G000028-CP02G000029 | EA34: CP02G000028-CP02G000029 | EB34: intergenic_region | EC34: CP02G000028-CP02G000029 | EF34: n.55683A>G
A35: 2 | B35: 60284 | C35: 2__60284 | D35: T | E35: =VLOOKUP(C35,significant_snps!#REF!,6,FALSE) -> #REF! | F35: ANN=G | G35: missense_variant | H35: MODERATE | I35: CP02G000032 | J35: cgd_2g150 | K35: CP02G000032 | L35: hypothetical protein | M35: CP02G000032.mRNA1 | N35: protein_coding | O35: 1/1 | P35: c.395T>G | Q35: p.Phe132Cys | R35: 395/975 | S35: 395/975 | T35: 132/324 | U35: ,G | V35: upstream_gene_variant | W35: MODIFIER | X35: CP02G000030 | Y35: CP02G000030 | Z35: transcript | AA35: CP02G000030.mRNA1 | AB35: protein_coding | AC35: c.-2965A>C | AD35: 2965 | AE35: ,G | AF35: upstream_gene_variant | AG35: MODIFIER | AH35: CP02G000034 | AI35: CP02G000034 | AJ35: transcript | AK35: CP02G000034.mRNA1 | AL35: protein_coding | AM35: c.-1937T>G | AN35: 1937 | AO35: ,G | AP35: upstream_gene_variant | AQ35: MODIFIER | AR35: CP02G000036 | AS35: CP02G000036 | AT35: transcript | AU35: CP02G000036.mRNA1 | AV35: protein_coding | AW35: c.-4019T>G | AX35: 4019 | AY35: ,G | AZ35: downstream_gene_variant | BA35: MODIFIER | BB35: CP02G000029 | BC35: CP02G000029 | BD35: transcript | BE35: CP02G000029.mRNA1 | BF35: protein_coding | BG35: c.*3732T>G | BH35: 3732 | BI35: ,G | BJ35: downstream_gene_variant | BK35: MODIFIER | BL35: CP02G000031 | BM35: CP02G000031 | BN35: transcript | BO35: CP02G000031.mRNA1 | BP35: protein_coding | BQ35: c.*1203T>G | BR35: 1203 | BS35: ,G | BT35: downstream_gene_variant | BU35: MODIFIER | BV35: CP02G000033 | BW35: CP02G000033 | BX35: transcript | BY35: CP02G000033.mRNA1 | BZ35: protein_coding | CA35: c.*783A>C | CB35: 783 | CC35: ,G | CD35: downstream_gene_variant | CE35: MODIFIER | CF35: CP02G000035 | CG35: CP02G000035 | CH35: transcript | CI35: CP02G000035.mRNA1 | CJ35: protein_coding | CK35: c.*2680A>C | CL35: 2680 | DB35: c.*783A>C | DG35: 783 | DH35: ,G | DI35: downstream_gene_variant | DJ35: MODIFIER | DK35: CP02G000035 | DL35: CP02G000035 | DM35: transcript | DN35: CP02G000035.mRNA1 | DO35: protein_coding | DQ35: c.*2680A>C | DV35: 2680
A36: 2 | B36: 65095 | C36: 2__65095 | D36: C | E36: =VLOOKUP(C36,significant_snps!#REF!,6,FALSE) -> #REF! | F36: ANN=T | G36: synonymous_variant | H36: LOW | I36: CP02G000036 | J36: cgd_2g110 | K36: CP02G000036 | L36: eIF4a-1-like RNA SFII helicase Dbp6p | M36: CP02G000036.mRNA1 | N36: protein_coding | O36: 2/2 | P36: c.726C>T | Q36: p.Pro242Pro | R36: 726/1611 | S36: 726/1611 | T36: 242/536 | U36: ,T | V36: upstream_gene_variant | W36: MODIFIER | X36: CP02G000033 | Y36: CP02G000033 | Z36: transcript | AA36: CP02G000033.mRNA1 | AB36: protein_coding | AC36: c.-3707G>A | AD36: 3707 | AE36: ,T | AF36: upstream_gene_variant | AG36: MODIFIER | AH36: CP02G000035 | AI36: CP02G000035 | AJ36: transcript | AK36: CP02G000035.mRNA1 | AL36: protein_coding | AM36: c.-1787G>A | AN36: 1787 | AO36: ,T | AP36: upstream_gene_variant | AQ36: MODIFIER | AR36: CP02G000037 | AS36: CP02G000037 | AT36: transcript | AU36: CP02G000037.mRNA1 | AV36: protein_coding | AW36: c.-2096C>T | AX36: 2096 | AY36: ,T | AZ36: upstream_gene_variant | BA36: MODIFIER | BB36: CP02G000038 | BC36: CP02G000038 | BD36: transcript | BE36: CP02G000038.mRNA1 | BF36: protein_coding | BG36: c.-4196C>T | BH36: 4196 | BI36: ,T | BJ36: downstream_gene_variant | BK36: MODIFIER | BL36: CP02G000032 | BM36: CP02G000032 | BN36: transcript | BO36: CP02G000032.mRNA1 | BP36: protein_coding | BQ36: c.*4231C>T | BR36: 4231 | BS36: ,T | BT36: downstream_gene_variant | BU36: MODIFIER | BV36: CP02G000034 | BW36: CP02G000034 | BX36: transcript | BY36: CP02G000034.mRNA1 | BZ36: protein_coding | CA36: c.*2536C>T | CB36: 2536 | DB36: c.*2536C>T | DG36: 2536
A37: 2 | B37: 65932 | C37: 2__65932 | D37: G | E37: =VLOOKUP(C37,significant_snps!#REF!,6,FALSE) -> #REF! | F37: ANN=T | G37: missense_variant | H37: MODERATE | I37: CP02G000036 | J37: cgd_2g110 | K37: CP02G000036 | L37: eIF4a-1-like RNA SFII helicase Dbp6p | M37: CP02G000036.mRNA1 | N37: protein_coding | O37: 2/2 | P37: c.1563G>T | Q37: p.Gln521His | R37: 1563/1611 | S37: 1563/1611 | T37: 521/536 | U37: ,T | V37: upstream_gene_variant | W37: MODIFIER | X37: CP02G000033 | Y37: CP02G000033 | Z37: transcript | AA37: CP02G000033.mRNA1 | AB37: protein_coding | AC37: c.-4544C>A | AD37: 4544 | AE37: ,T | AF37: upstream_gene_variant | AG37: MODIFIER | AH37: CP02G000035 | AI37: CP02G000035 | AJ37: transcript | AK37: CP02G000035.mRNA1 | AL37: protein_coding | AM37: c.-2624C>A | AN37: 2624 | AO37: ,T | AP37: upstream_gene_variant | AQ37: MODIFIER | AR37: CP02G000037 | AS37: CP02G000037 | AT37: transcript | AU37: CP02G000037.mRNA1 | AV37: protein_coding | AW37: c.-1259G>T | AX37: 1259 | AY37: ,T | AZ37: upstream_gene_variant | BA37: MODIFIER | BB37: CP02G000038 | BC37: CP02G000038 | BD37: transcript | BE37: CP02G000038.mRNA1 | BF37: protein_coding | BG37: c.-3359G>T | BH37: 3359 | BI37: ,T | BJ37: downstream_gene_variant | BK37: MODIFIER | BL37: CP02G000034 | BM37: CP02G000034 | BN37: transcript | BO37: CP02G000034.mRNA1 | BP37: protein_coding | BQ37: c.*3373G>T | BR37: 3373
A38: 2 | B38: 98233 | C38: 2__98233 | D38: G | E38: =VLOOKUP(C38,significant_snps!#REF!,6,FALSE) -> #REF! | F38: ANN=A | G38: synonymous_variant | H38: LOW | I38: CP02G000045 | J38: CP03G000353 | K38: CP02G000045 | L38: #N/A | M38: CP02G000045.mRNA1 | N38: protein_coding | O38: 1/1 | P38: c.1965C>T | Q38: p.Gly655Gly | R38: 1965/2034 | S38: 1965/2034 | T38: 655/677 | U38: ,A | V38: upstream_gene_variant | W38: MODIFIER | X38: CP02G000044 | Y38: CP02G000044 | Z38: transcript | AA38: CP02G000044.mRNA1 | AB38: protein_coding | AC38: c.-1139C>T | AD38: 1139 | AE38: ,A | AF38: upstream_gene_variant | AG38: MODIFIER | AH38: CP02G000046 | AI38: CP02G000046 | AJ38: transcript | AK38: CP02G000046.mRNA1 | AL38: protein_coding | AM38: c.-3748G>A | AN38: 3748 | AO38: ,A | AP38: downstream_gene_variant | AQ38: MODIFIER | AR38: CP02G000043 | AS38: CP02G000043 | AT38: transcript | AU38: CP02G000043.mRNA1 | AV38: protein_coding | AW38: c.*2729G>A | AX38: 2729
A39: 2 | B39: 98242 | C39: 2__98242 | D39: T | E39: =VLOOKUP(C39,significant_snps!#REF!,6,FALSE) -> #REF! | F39: ANN=A | G39: synonymous_variant | H39: LOW | I39: CP02G000045 | J39: CP03G000353 | K39: CP02G000045 | L39: #N/A | M39: CP02G000045.mRNA1 | N39: protein_coding | O39: 1/1 | P39: c.1956A>T | Q39: p.Gly652Gly | R39: 1956/2034 | S39: 1956/2034 | T39: 652/677 | U39: ,A | V39: upstream_gene_variant | W39: MODIFIER | X39: CP02G000044 | Y39: CP02G000044 | Z39: transcript | AA39: CP02G000044.mRNA1 | AB39: protein_coding | AC39: c.-1148A>T | AD39: 1148 | AE39: ,A | AF39: upstream_gene_variant | AG39: MODIFIER | AH39: CP02G000046 | AI39: CP02G000046 | AJ39: transcript | AK39: CP02G000046.mRNA1 | AL39: protein_coding | AM39: c.-3739T>A | AN39: 3739 | AO39: ,A | AP39: downstream_gene_variant | AQ39: MODIFIER | AR39: CP02G000043 | AS39: CP02G000043 | AT39: transcript | AU39: CP02G000043.mRNA1 | AV39: protein_coding | AW39: c.*2738T>A | AX39: 2738
A40: 2 | B40: 98245 | C40: 2__98245 | D40: A | E40: =VLOOKUP(C40,significant_snps!#REF!,6,FALSE) -> #REF! | F40: ANN=G | G40: synonymous_variant | H40: LOW | I40: CP02G000045 | J40: CP03G000353 | K40: CP02G000045 | L40: #N/A | M40: CP02G000045.mRNA1 | N40: protein_coding | O40: 1/1 | P40: c.1953T>C | Q40: p.Gly651Gly | R40: 1953/2034 | S40: 1953/2034 | T40: 651/677 | U40: ,G | V40: upstream_gene_variant | W40: MODIFIER | X40: CP02G000044 | Y40: CP02G000044 | Z40: transcript | AA40: CP02G000044.mRNA1 | AB40: protein_coding | AC40: c.-1151T>C | AD40: 1151 | AE40: ,G | AF40: upstream_gene_variant | AG40: MODIFIER | AH40: CP02G000046 | AI40: CP02G000046 | AJ40: transcript | AK40: CP02G000046.mRNA1 | AL40: protein_coding | AM40: c.-3736A>G | AN40: 3736 | AO40: ,G | AP40: downstream_gene_variant | AQ40: MODIFIER | AR40: CP02G000043 | AS40: CP02G000043 | AT40: transcript | AU40: CP02G000043.mRNA1 | AV40: protein_coding | AW40: c.*2741A>G | AX40: 2741
...

Sheet Candidate-gene-3-8-11-24
A1: GeneID | B1: ID | C1: Annotation
A2: CP01G000011 | B2: CPCDC_1g110 | C2: hypothetical protein
A3: CP01G000014 | B3: CPCDC_1g140 | C3: hypothetical protein
A4: CP01G000017 | B4: CPCDC_1g170 | C4: hypothetical protein
A5: CP01G000031 | B5: CPCDC_1g300 | C5: 40S ribosomal protein S21
A6: CP01G000027 | B6: CPCDC_1g260 | C6: putative signal peptide-containing secreted
A7: CP01G000035 | B7: CPCDC_1g340 | C7: hypothetical protein
A8: CP01G000034 | B8: CPCDC_1g330 | C8: CDC48-like AAA ATPase
A9: CP01G000036 | B9: CPCDC_1g350 | C9: hypothetical protein
A10: CP01G000037 | B10: CPCDC_1g360 | C10: hypothetical protein
A11: CP01G000048 | B11: CPCDC_1g470 | C11: mucin-like protein
A12: CP01G000047 | B12: CPCDC_1g460 | C12: hypothetical protein
... A178: CP03G000060 | B178: CPCDC_3g580 | C178: putative signal peptide-containing protein plus
